<?xml version="1.0"?>
<!-- This URDF was automatically created by SolidWorks to URDF Exporter! Originally created by Stephen Brawner (brawner@gmail.com) 
     Commit Version: 1.6.0-4-g7f85cfe  Build Version: 1.6.7995.38578
     For more information, please see http://wiki.ros.org/sw_urdf_exporter -->
<robot
  name="my_team_robot">
  <link
    name="base_link">
    <inertial>
      <origin
        xyz="-0.016824 7.1346E-09 -0.0076023"
        rpy="0 0 0" />
      <mass
        value="0.095337" />
      <inertia
        ixx="5.9484E-05"
        ixy="1.9529E-11"
        ixz="-8.9959E-07"
        iyy="9.8649E-05"
        iyz="-1.6019E-12"
        izz="0.00015418" />
    </inertial>
    <visual>
      <origin
        xyz="0 0 0"
        rpy="0 0 0" />
      <geometry>
        <mesh
          filename="package://my_team_robot/meshes/base_link.STL" />
      </geometry>
      <material
        name="">
        <color
          rgba="0.79216 0.81961 0.93333 1" />
      </material>
    </visual>
    <collision>
      <origin
        xyz="0 0 0"
        rpy="0 0 0" />
      <geometry>
        <mesh
          filename="package://my_team_robot/meshes/base_link.STL" />
      </geometry>
    </collision>
  </link>
  <link
    name="leftwheel">
    <inertial>
      <origin
        xyz="2.3592E-16 2.7756E-17 0.0064675"
        rpy="0 0 0" />
      <mass
        value="0.014896" />
      <inertia
        ixx="3.4328E-06"
        ixy="-1.4494E-21"
        ixz="2.6442E-21"
        iyy="3.4328E-06"
        iyz="2.7406E-22"
        izz="6.1544E-06" />
    </inertial>
    <visual>
      <origin
        xyz="0 0 0"
        rpy="0 0 0" />
      <geometry>
        <mesh
          filename="package://my_team_robot/meshes/leftwheel.STL" />
      </geometry>
      <material
        name="">
        <color
          rgba="0.79216 0.81961 0.93333 1" />
      </material>
    </visual>
    <collision>
      <origin
        xyz="0 0 0"
        rpy="0 0 0" />
      <geometry>
        <mesh
          filename="package://my_team_robot/meshes/leftwheel.STL" />
      </geometry>
    </collision>
  </link>
  <joint
    name="left_wheel"
    type="continuous">
    <origin
      xyz="-0.018999 0.0808 -0.0141"
      rpy="1.5708 0 0" />
    <parent
      link="base_link" />
    <child
      link="leftwheel" />
    <axis
      xyz="0 0 -1" />
    <limit
      effort="10"
      velocity="10" />
    <dynamics
      damping="0.1"
      friction="0.1" />
  </joint>
  <link
    name="rightwheel">
    <inertial>
      <origin
        xyz="-2.3592E-16 -3.1919E-16 -0.0064675"
        rpy="0 0 0" />
      <mass
        value="0.014896" />
      <inertia
        ixx="3.4328E-06"
        ixy="-4.0996E-23"
        ixz="-1.0497E-21"
        iyy="3.4328E-06"
        iyz="-2.8625E-21"
        izz="6.1544E-06" />
    </inertial>
    <visual>
      <origin
        xyz="0 0 0"
        rpy="0 0 0" />
      <geometry>
        <mesh
          filename="package://my_team_robot/meshes/rightwheel.STL" />
      </geometry>
      <material
        name="">
        <color
          rgba="0.79216 0.81961 0.93333 1" />
      </material>
    </visual>
    <collision>
      <origin
        xyz="0 0 0"
        rpy="0 0 0" />
      <geometry>
        <mesh
          filename="package://my_team_robot/meshes/rightwheel.STL" />
      </geometry>
    </collision>
  </link>
  <joint
    name="right_wheel"
    type="continuous">
    <origin
      xyz="-0.018999 -0.0808 -0.0141"
      rpy="1.5708 0 0" />
    <parent
      link="base_link" />
    <child
      link="rightwheel" />
    <axis
      xyz="0 0 1" />
    <limit
      effort="10"
      velocity="10" />
    <dynamics
      damping="0.1"
      friction="0.1" />
  </joint>
  <link
    name="conquay">
    <inertial>
      <origin
        xyz="0 0 -0.012786"
        rpy="0 0 0" />
      <mass
        value="0.00075181" />
      <inertia
        ixx="5.6519E-08"
        ixy="4.3148E-09"
        ixz="-2.7696E-24"
        iyy="6.1864E-08"
        iyz="-5.7454E-24"
        izz="2.4909E-08" />
    </inertial>
    <visual>
      <origin
        xyz="0 0 0"
        rpy="0 0 0" />
      <geometry>
        <mesh
          filename="package://my_team_robot/meshes/conquay.STL" />
      </geometry>
      <material
        name="">
        <color
          rgba="0.79216 0.81961 0.93333 1" />
      </material>
    </visual>
    <collision>
      <origin
        xyz="0 0 0"
        rpy="0 0 0" />
      <geometry>
        <mesh
          filename="package://my_team_robot/meshes/conquay.STL" />
      </geometry>
    </collision>
  </link>
  <joint
    name="con_quay"
    type="continuous">
    <origin
      xyz="0.058851 0 -0.003"
      rpy="0 0 0" />
    <parent
      link="base_link" />
    <child
      link="conquay" />
    <axis
      xyz="0 0 1" />
    <limit
      effort="10"
      velocity="10" />
    <dynamics
      damping="0.1"
      friction="0.1" />
  </joint>
  <link
    name="wheelmini">
    <inertial>
      <origin
        xyz="-0.0017473 4.1633E-17 -0.0009731"
        rpy="0 0 0" />
      <mass
        value="0.0031218" />
      <inertia
        ixx="2.6447E-07"
        ixy="-3.0475E-22"
        ixz="5.467E-08"
        iyy="1.663E-07"
        iyz="2.8714E-22"
        izz="1.9675E-07" />
    </inertial>
    <visual>
      <origin
        xyz="0 0 0"
        rpy="0 0 0" />
      <geometry>
        <mesh
          filename="package://my_team_robot/meshes/wheelmini.STL" />
      </geometry>
      <material
        name="">
        <color
          rgba="0.79216 0.81961 0.93333 1" />
      </material>
    </visual>
    <collision>
      <origin
        xyz="0 0 0"
        rpy="0 0 0" />
      <geometry>
        <mesh
          filename="package://my_team_robot/meshes/wheelmini.STL" />
      </geometry>
    </collision>
  </link>
  <joint
    name="wheel_mini"
    type="continuous">
    <origin
      xyz="0.0017473 -0.0009731 -0.0236"
      rpy="1.5708 0 0" />
    <parent
      link="conquay" />
    <child
      link="wheelmini" />
    <axis
      xyz="0.87365 0 0.48655" />
    <limit
      effort="10"
      velocity="10" />
    <dynamics
      damping="0.1"
      friction="0.1" />
  </joint>

  <!-- Adjusted friction and gravity settings in Gazebo -->
  <gazebo reference="base_link">
    <mu1>1000</mu1>
    <mu2>1000</mu2>
    <gravity>1</gravity>
    <material>Gazebo/Green</material>
  </gazebo>

  <!-- Adjusted dynamics and friction for wheels -->
  <gazebo reference="leftwheel">
    <mu1>1000</mu1>
    <mu2>1000</mu2>
    <material>Gazebo/Grey</material>
  </gazebo>

  <gazebo reference="right_wheel">
    <mu1>1000</mu1>
    <mu2>1000</mu2>
    <material>Gazebo/Grey</material>
  </gazebo>

  <gazebo reference="con_quay">
    <mu1>1000</mu1>
    <mu2>1000</mu2>
    <material>Gazebo/Grey</material>
  </gazebo>

  <gazebo reference="wheel_mini">
    <mu1>1000</mu1>
    <mu2>1000</mu2>
    <material>Gazebo/Grey</material>
  </gazebo>

  <gazebo>
    <plugin name="four_wheeled_robot_diff_drive" filename="libgazebo_ros_diff_drive.so">
 
      <update_rate>100</update_rate>
      <num_wheel_pairs>1</num_wheel_pairs>
      <!-- wheels -->
      <left_joint>left_wheel</left_joint>
      <right_joint>right_wheel</right_joint>

      <!-- kinematics -->
      <wheel_separation>0.135</wheel_separation> <!-- Khoảng cách giữa các bánh trước và sau -->
      <wheel_diameter>0.073</wheel_diameter> <!-- Đường kính bánh xe -->
 
      <!-- limits -->
      <max_wheel_torque>30</max_wheel_torque>
      <max_wheel_acceleration>30.0</max_wheel_acceleration>
 
      <!-- Receive velocity commands on this ROS topic -->
      <command_topic>cmd_vel</command_topic>
 
      <!-- output -->
      <!-- When false, publish no wheel odometry data to a ROS topic -->
      <publish_odom>true</publish_odom>
 
      <!-- When true, publish coordinate transform from odom to base_footprint -->
      <publish_odom_tf>true</publish_odom_tf>
     
      <!-- When true, publish coordinate transform from base_link to the wheels -->
      <publish_wheel_tf>true</publish_wheel_tf>
 
      <odometry_topic>odom</odometry_topic>
      <odometry_frame>odom_link</odometry_frame>
      <robot_base_frame>base_link</robot_base_frame>
 
      <odometry_source>1</odometry_source>
      <ros>
        <remapping>odom:=wheel/odometry</remapping>
      </ros>
    </plugin>
  </gazebo>

  <gazebo>
      <plugin name="gazebo_ros_joint_state_publisher"
          filename="libgazebo_ros_joint_state_publisher.so">
          <update_rate>100</update_rate>
          <joint_name>left_wheel</joint_name>
          <joint_name>right_wheel</joint_name>
      </plugin>
  </gazebo>
</robot>