<?xml version="1.0" encoding="utf-8"?>
<!-- This URDF was automatically created by SolidWorks to URDF Exporter! Originally created by Stephen Brawner (brawner@gmail.com) 
     Commit Version: 1.6.0-4-g7f85cfe  Build Version: 1.6.7995.38578
     For more information, please see http://wiki.ros.org/sw_urdf_exporter -->
<robot
  name="my_team_robot">
  <link
    name="base_link">
    <inertial>
      <origin
        xyz="-0.0168237810190544 7.13458084972141E-09 -0.00760225410164192"
        rpy="0 0 0" />
      <mass
        value="0.0953373583617677" />
      <inertia
        ixx="5.94842863178214E-05"
        ixy="1.95289627130984E-11"
        ixz="-8.9958564906486E-07"
        iyy="9.86494627792786E-05"
        iyz="-1.60193586284062E-12"
        izz="0.000154178001735707" />
    </inertial>
    <visual>
      <origin
        xyz="0 0 0"
        rpy="0 0 0" />
      <geometry>
        <mesh
          filename="package://my_team_robot/meshes/base_link.STL" />
      </geometry>
      <material
        name="">
        <color
          rgba="0.792156862745098 0.819607843137255 0.933333333333333 1" />
      </material>
    </visual>
    <collision>
      <origin
        xyz="0 0 0"
        rpy="0 0 0" />
      <geometry>
        <mesh
          filename="package://my_team_robot/meshes/base_link.STL" />
      </geometry>
    </collision>
  </link>
  <link
    name="leftwheel">
    <inertial>
      <origin
        xyz="6.9389E-17 0 0.0064675"
        rpy="0 0 0" />
      <mass
        value="0.014896" />
      <inertia
        ixx="3.4328E-06"
        ixy="-1.3702E-22"
        ixz="2.8683E-21"
        iyy="3.4328E-06"
        iyz="-7.4454E-22"
        izz="6.1544E-06" />
    </inertial>
    <visual>
      <origin
        xyz="0 0 0"
        rpy="0 0 0" />
      <geometry>
        <mesh
          filename="package://my_team_robot/meshes/leftwheel.STL" />
      </geometry>
      <material
        name="">
        <color
          rgba="0.79216 0.81961 0.93333 1" />
      </material>
    </visual>
    <collision>
      <origin
        xyz="0 0 0"
        rpy="0 0 0" />
      <geometry>
        <mesh
          filename="package://my_team_robot/meshes/leftwheel.STL" />
      </geometry>
    </collision>
  </link>
  <joint
    name="left_wheel"
    type="continuous">
    <origin
      xyz="-0.018999 0.0808 -0.0141"
      rpy="1.5708 0 0" />
    <parent
      link="base_link" />
    <child
      link="leftwheel" />
    <axis
      xyz="0 0 -1" />
    <limit
      effort="10"
      velocity="10" />
    <dynamics
      damping="0.1"
      friction="0.1" />
  </joint>
  <link
    name="rightwheel">
    <inertial>
      <origin
        xyz="0 -5.5511E-17 -0.0064675"
        rpy="0 0 0" />
      <mass
        value="0.014896" />
      <inertia
        ixx="3.4328E-06"
        ixy="2.8475E-22"
        ixz="4.5719E-22"
        iyy="3.4328E-06"
        iyz="3.0947E-21"
        izz="6.1544E-06" />
    </inertial>
    <visual>
      <origin
        xyz="0 0 0"
        rpy="0 0 0" />
      <geometry>
        <mesh
          filename="package://my_team_robot/meshes/rightwheel.STL" />
      </geometry>
      <material
        name="">
        <color
          rgba="0.79216 0.81961 0.93333 1" />
      </material>
    </visual>
    <collision>
      <origin
        xyz="0 0 0"
        rpy="0 0 0" />
      <geometry>
        <mesh
          filename="package://my_team_robot/meshes/rightwheel.STL" />
      </geometry>
    </collision>
  </link>
  <joint
    name="right_wheel"
    type="continuous">
    <origin
      xyz="-0.018999 -0.0808 -0.0141"
      rpy="1.5708 0 0" />
    <parent
      link="base_link" />
    <child
      link="rightwheel" />
    <axis
      xyz="0 0 1" />
    <limit
      effort="10"
      velocity="10" />
    <dynamics
      damping="0.1"
      friction="0.1" />
  </joint>
  <link
    name="conquay">
    <inertial>
      <origin
        xyz="-0.0028851 0.00054871 -0.010118"
        rpy="0 0 0" />
      <mass
        value="0.00084993" />
      <inertia
        ixx="6.8227E-08"
        ixy="-4.9992E-10"
        ixz="-1.6544E-08"
        iyy="6.5695E-08"
        iyz="3.1461E-09"
        izz="3.908E-08" />
    </inertial>
    <visual>
      <origin
        xyz="0 0 0"
        rpy="0 0 0" />
      <geometry>
        <mesh
          filename="package://my_team_robot/meshes/conquay.STL" />
      </geometry>
      <material
        name="">
        <color
          rgba="0.79216 0.81961 0.93333 1" />
      </material>
    </visual>
    <collision>
      <origin
        xyz="0 0 0"
        rpy="0 0 0" />
      <geometry>
        <mesh
          filename="package://my_team_robot/meshes/conquay.STL" />
      </geometry>
    </collision>
  </link>
  <joint
    name="con_quay"
    type="continuous">
    <origin
      xyz="0.058851 0 -0.003"
      rpy="0 0 0" />
    <parent
      link="base_link" />
    <child
      link="conquay" />
    <axis
      xyz="0 0 1" />
    <limit
      effort="10"
      velocity="10" />
    <dynamics
      damping="0.1"
      friction="0.1" />
  </joint>
  <link
    name="wheelmini">
    <inertial>
      <origin
        xyz="-0.00037366 1.3878E-17 0.0019648"
        rpy="0 0 0" />
      <mass
        value="0.0031218" />
      <inertia
        ixx="1.7079E-07"
        ixy="3.8469E-22"
        ixz="-2.3606E-08"
        iyy="1.663E-07"
        iyz="2.1953E-22"
        izz="2.9043E-07" />
    </inertial>
    <visual>
      <origin
        xyz="0 0 0"
        rpy="0 0 0" />
      <geometry>
        <mesh
          filename="package://my_team_robot/meshes/wheelmini.STL" />
      </geometry>
      <material
        name="">
        <color
          rgba="0.79216 0.81961 0.93333 1" />
      </material>
    </visual>
    <collision>
      <origin
        xyz="0 0 0"
        rpy="0 0 0" />
      <geometry>
        <mesh
          filename="package://my_team_robot/meshes/wheelmini.STL" />
      </geometry>
    </collision>
  </link>
  <joint
    name="wheel_mini"
    type="continuous">
    <origin
      xyz="-0.00748548418996223 0.00345941128543842 -0.0236000000000019"
      rpy="1.5707963267949 0 0" />
    <parent
      link="conquay" />
    <child
      link="wheelmini" />
    <axis
      xyz="0.186828263287934 0 -0.982392589567335" />
  </joint>
</robot>